<mujoco model="dragon">
    <compiler angle="radian" meshdir="meshes/"/>
    <option timestep="0.001"  tolerance="1e-10" solver="Newton" jacobian="dense" cone="pyramidal" gravity="0 0 -9.81">  <!--integrator="RK4"  iteration="50"-->
        <flag contact="enable" energy="enable"/>
    </option>
    <size njmax="500" nconmax="1000" />  
    <default>
        <light castshadow="false" />
        <geom rgba="0.784 0.784 0.784 1"/>
        <default class="visual">
            <geom contype="0" conaffinity="0" group="1" type="mesh" euler="1.57 0 0" />
        </default>
        <default class="collision">
            <geom contype="1" conaffinity="1" friction="1.0 0.3 0.3" 
                margin="0.001" group="0" euler="1.57 0 0" />
        </default>
        <joint damping="0.1" frictionloss="0.02" armature="0.01"/>
    </default>
    <asset>
        <mesh name="LF_hip" file="LF_hip.STL" />
        <mesh name="LF_thigh" file="LF_thigh.STL" />
        <mesh name="LF_calf" file="LF_calf.STL" />
        <mesh name="RF_hip" file="RF_hip.STL" />
        <mesh name="RF_thigh" file="RF_thigh.STL" />
        <mesh name="RF_calf" file="RF_calf.STL" />
        <mesh name="LH_hip" file="LH_hip.STL" />
        <mesh name="LH_thigh" file="LH_thigh.STL" />
        <mesh name="LH_calf" file="LH_calf.STL" />
        <mesh name="RH_hip" file="RH_hip.STL" />
        <mesh name="RH_thigh" file="RH_thigh.STL" />
        <mesh name="RH_calf" file="RH_calf.STL" />
    </asset>
    <worldbody>
        <body name="base" pos="0 0 0.5">
            <freejoint name="float_base" />
            <inertial  pos="-0.0066829 0.00029137 0.021473" mass="6.5145" fullinertia="0.049188 0.090843 0.12536 0.00010956 0.001009 -1.223E-05" />
            <geom size="0.2 0.11 0.05" type="box" contype="0" conaffinity="0" group="1" rgba="0.75294 0.75294 0.75294 1" />
            <geom size="0.2 0.11 0.05" type="box" rgba="0.75294 0.75294 0.75294 1" />
            <site name="imu" quat="1 0 0 0"/>
            <body name="LF_hip" pos="0.30236 0.07 -0.004">
                <inertial pos="-0.0096065 -0.010937 3.9018e-06" quat="0.500702 0.496272 0.499057 0.503939" mass="0.32023" diaginertia="0.000670222 0.000380973 0.000343735" />
                <joint name="LF_HAA" pos="0 0 0" axis="1 0 0" limited="true" range="-3.14 3.14" />
                <geom type="mesh" contype="0" conaffinity="0" group="1" rgba="0.75294 0.75294 0.75294 1" mesh="LF_hip" />
                <geom type="mesh" rgba="0.75294 0.75294 0.75294 1" mesh="LF_hip" />
                <body name="LF_thigh" pos="0 0 0">
                    <inertial pos="-0.0036513 0.082785 -0.055599" quat="0.705895 0.0240178 0.0292023 0.707306" mass="0.45053" diaginertia="0.00279273 0.00240314 0.000415147" />
                    <joint name="LF_HFE" pos="0 0 0" axis="0 1 0" limited="true" range="-3.14 3.14" />
                    <geom type="mesh" contype="0" conaffinity="0" group="1" rgba="0.75294 0.75294 0.75294 1" mesh="LF_thigh" />
                    <geom type="mesh" rgba="0.75294 0.75294 0.75294 1" mesh="LF_thigh" />
                    <body name="LF_calf" pos="0 0.1057 -0.28">
                        <inertial pos="0.00154091 8.54632e-09 -0.213612" quat="0.707105 -0.00308675 -0.00309841 0.707095" mass="0.137851" diaginertia="0.00104049 0.0010324 2.12109e-05" />
                        <joint name="LF_KFE" pos="0 0 0" axis="0 1 0" limited="true" range="-3.14 3.14" />
                        <geom type="mesh" contype="0" conaffinity="0" group="1" rgba="0.75294 0.75294 0.75294 1" mesh="LF_calf" />
                        <geom type="mesh" rgba="0.75294 0.75294 0.75294 1" mesh="LF_calf" />
                        <geom size="0.01" pos="0 0 -0.2668" contype="0" conaffinity="0" group="1" />
                        <geom size="0.02" pos="0 0 -0.2668" />
                    </body>
                </body>
            </body>
            <body name="RF_hip" pos="0.30236 -0.07 -0.004">
                <inertial pos="-0.0096065 0.010937 -4.1917e-06" quat="0.499054 0.503941 0.500704 0.496269" mass="0.32023" diaginertia="0.000670222 0.000380973 0.000343735" />
                <joint name="RF_HAA" pos="0 0 0" axis="1 0 0" limited="true" range="-3.14 3.14" />
                <geom type="mesh" contype="0" conaffinity="0" group="1" rgba="0.75294 0.75294 0.75294 1" mesh="RF_hip" />
                <geom type="mesh" rgba="0.75294 0.75294 0.75294 1" mesh="RF_hip" />
                <body name="RF_thigh" pos="0 0 0">
                    <inertial pos="-0.003594 -0.082799 -0.055838" quat="0.707184 0.030494 0.0253656 0.705916" mass="0.45095" diaginertia="0.00280073 0.00240658 0.000419726" />
                    <joint name="RF_HFE" pos="0 0 0" axis="0 1 0" limited="true" range="-3.14 3.14" />
                    <geom type="mesh" contype="0" conaffinity="0" group="1" rgba="0.75294 0.75294 0.75294 1" mesh="RF_thigh" />
                    <geom type="mesh" rgba="0.75294 0.75294 0.75294 1" mesh="RF_thigh" />
                    <body name="RF_calf" pos="0 -0.1057 -0.28">
                        <inertial pos="0.00154091 8.54802e-09 -0.213612" quat="0.707105 -0.00308675 -0.00309841 0.707095" mass="0.137851" diaginertia="0.00104049 0.0010324 2.12109e-05" />
                        <joint name="RF_KFE" pos="0 0 0" axis="0 1 0" limited="true" range="-3.14 3.14" />
                        <geom type="mesh" contype="0" conaffinity="0" group="1" rgba="0.75294 0.75294 0.75294 1" mesh="RF_calf" />
                        <geom type="mesh" rgba="0.75294 0.75294 0.75294 1" mesh="RF_calf" />
                        <geom size="0.01" pos="0 0 -0.2668" contype="0" conaffinity="0" group="1" />
                        <geom size="0.02" pos="0 0 -0.2668" />
                    </body>
                </body>
            </body>
            <body name="LH_hip" pos="-0.30236 0.07 -0.004">
                <inertial pos="0.0096065 -0.010937 -3.9018e-06" quat="0.503939 0.499057 0.496272 0.500702" mass="0.32023" diaginertia="0.000670222 0.000380973 0.000343735" />
                <joint name="LH_HAA" pos="0 0 0" axis="1 0 0" limited="true" range="-3.14 3.14" />
                <geom type="mesh" contype="0" conaffinity="0" group="1" rgba="0.75294 0.75294 0.75294 1" mesh="LH_hip" />
                <geom type="mesh" rgba="0.75294 0.75294 0.75294 1" mesh="LH_hip" />
                <body name="LH_thigh" pos="0 0 0">
                    <inertial pos="-0.0036513 0.082785 -0.055599" quat="0.705895 0.0240178 0.0292023 0.707306" mass="0.45053" diaginertia="0.00279273 0.00240314 0.000415147" />
                    <joint name="LH_HFE" pos="0 0 0" axis="0 1 0" limited="true" range="-3.14 3.14" />
                    <geom type="mesh" contype="0" conaffinity="0" group="1" rgba="0.75294 0.75294 0.75294 1" mesh="LH_thigh" />
                    <geom type="mesh" rgba="0.75294 0.75294 0.75294 1" mesh="LH_thigh" />
                    <body name="LH_calf" pos="0 0.1057 -0.28">
                        <inertial pos="0.00154091 8.54632e-09 -0.213612" quat="0.707105 -0.00308675 -0.00309841 0.707095" mass="0.137851" diaginertia="0.00104049 0.0010324 2.12109e-05" />
                        <joint name="LH_KFE" pos="0 0 0" axis="0 1 0" limited="true" range="-3.14 3.14" />
                        <geom type="mesh" contype="0" conaffinity="0" group="1" rgba="0.75294 0.75294 0.75294 1" mesh="LH_calf" />
                        <geom type="mesh" rgba="0.75294 0.75294 0.75294 1" mesh="LH_calf" />
                        <geom size="0.01" pos="0 0 -0.2668" contype="0" conaffinity="0" group="1" />
                        <geom size="0.02" pos="0 0 -0.2668" />
                    </body>
                </body>
            </body>
            <body name="RH_hip" pos="-0.30236 -0.07 -0.004">
                <inertial pos="0.0096065 0.010937 4.1917e-06" quat="0.500922 0.49605 0.499253 0.503744" mass="0.32023" diaginertia="0.000670222 0.000380973 0.000343735" />
                <joint name="RH_HAA" pos="0 0 0" axis="1 0 0" limited="true" range="-3.14 3.14" />
                <geom type="mesh" contype="0" conaffinity="0" group="1" rgba="0.75294 0.75294 0.75294 1" mesh="RH_hip" />
                <geom type="mesh" rgba="0.75294 0.75294 0.75294 1" mesh="RH_hip" />
                <body name="RH_thigh" pos="0 0 0">
                    <inertial pos="-0.003594 -0.082799 -0.055838" quat="0.707184 0.030494 0.0253656 0.705916" mass="0.45095" diaginertia="0.00280073 0.00240658 0.000419726" />
                    <joint name="RH_HFE" pos="0 0 0" axis="0 1 0" limited="true" range="-3.14 3.14" />
                    <geom type="mesh" contype="0" conaffinity="0" group="1" rgba="0.75294 0.75294 0.75294 1" mesh="RH_thigh" />
                    <geom type="mesh" rgba="0.75294 0.75294 0.75294 1" mesh="RH_thigh" />
                    <body name="RH_calf" pos="0 -0.1057 -0.28">
                        <inertial pos="0.00154091 8.54802e-09 -0.213612" quat="0.707105 -0.00308675 -0.00309841 0.707095" mass="0.137851" diaginertia="0.00104049 0.0010324 2.12109e-05" />
                        <joint name="RH_KFE" pos="0 0 0" axis="0 1 0" limited="true" range="-3.14 3.14" />
                        <geom type="mesh" contype="0" conaffinity="0" group="1" rgba="0.75294 0.75294 0.75294 1" mesh="RH_calf" />
                        <geom type="mesh" rgba="0.75294 0.75294 0.75294 1" mesh="RH_calf" />
                        <geom size="0.01" pos="0 0 -0.2668" contype="0" conaffinity="0" group="1" />
                        <geom size="0.02" pos="0 0 -0.2668" />
                    </body>
                </body>
            </body>
        </body>   
    </worldbody>
    <contact>
        <exclude name="ex_base_LF_hip" body1="base" body2="LF_hip" />
        <exclude name="ex_LF_hip_LF_thigh" body1="LF_hip" body2="LF_thigh" />
        <exclude name="ex_LF_thigh_LF_calf" body1="LF_thigh" body2="LF_calf" />

        <exclude name="ex_base_RF_hip" body1="base" body2="RF_hip" />
        <exclude name="ex_RF_hip_RF_thigh" body1="RF_hip" body2="RF_thigh" />
        <exclude name="ex_RF_thigh_RF_calf" body1="RF_thigh" body2="RF_calf" />

        <exclude name="ex_base_LH_hip" body1="base" body2="LH_hip" />
        <exclude name="ex_LH_hip_LH_thigh" body1="LH_hip" body2="LH_thigh" />
        <exclude name="ex_LH_thigh_LH_calf" body1="LH_thigh" body2="LH_calf" />

        <exclude name="ex_base_RH_hip" body1="base" body2="RH_hip" />
        <exclude name="ex_RH_hip_RH_thigh" body1="RH_hip" body2="RH_thigh" />
        <exclude name="ex_RH_thigh_RH_calf" body1="RH_thigh" body2="RH_calf" />
    </contact>
    <actuator>
        <motor name="M_LF_HAA"  joint="LF_HAA" gear="1" ctrllimited="true" ctrlrange="-50 50"/>
        <motor name="M_LF_HFE"  joint="LF_HFE" gear="1" ctrllimited="true" ctrlrange="-50 50"/>
        <motor name="M_LF_KFE"  joint="LF_KFE" gear="1" ctrllimited="true" ctrlrange="-50 50"/>

        <motor name="M_LH_HAA"  joint="LH_HAA" gear="1" ctrllimited="true" ctrlrange="-50 50"/>
        <motor name="M_LH_HFE"  joint="LH_HFE" gear="1" ctrllimited="true" ctrlrange="-50 50"/>
        <motor name="M_LH_KFE"  joint="LH_KFE" gear="1" ctrllimited="true" ctrlrange="-50 50"/>

        <motor name="M_RF_HAA"  joint="RF_HAA" gear="1" ctrllimited="true" ctrlrange="-50 50"/>
        <motor name="M_RF_HFE"  joint="RF_HFE" gear="1" ctrllimited="true" ctrlrange="-50 50"/>
        <motor name="M_RF_KFE"  joint="RF_KFE" gear="1" ctrllimited="true" ctrlrange="-50 50"/>

        <motor name="M_RH_HAA"  joint="RH_HAA" gear="1" ctrllimited="true" ctrlrange="-50 50"/>
        <motor name="M_RH_HFE"  joint="RH_HFE" gear="1" ctrllimited="true" ctrlrange="-50 50"/>
        <motor name="M_RH_KFE"  joint="RH_KFE" gear="1" ctrllimited="true" ctrlrange="-50 50"/>
    </actuator>
    <sensor>
        <framequat name="baselink-quat" objtype="site" objname="imu" />
        <velocimeter name="baselink-velocity" site="imu" />
        <gyro name="baselink-gyro" site="imu" />
        <accelerometer name="baselink-baseAcc" site="imu" />
    </sensor>
</mujoco>
