<?xml version="1.0" encoding="utf-8"?>
<!-- This URDF was automatically created by SolidWorks to URDF Exporter! Originally created by Stephen Brawner (brawner@gmail.com) 
     Commit Version: 1.5.1-0-g916b5db  Build Version: 1.5.7152.31018
     For more information, please see http://wiki.ros.org/sw_urdf_exporter -->
<robot
  name="dragon">
  <mujoco>
    <compiler
    	meshdir="meshes/"
    	balanceinertia="true"
    	discardvisual="false" />
  </mujoco>
  <link
    name="base">
    <inertial>
      <origin
        xyz="-0.0066829 0.00029137 0.021473"
        rpy="0 0 0" />
      <mass
        value="6.5145" />
      <inertia
        ixx="0.049188"
        ixy="0.00010956"
        ixz="0.001009"
        iyy="0.090843"
        iyz="-1.223E-05"
        izz="0.12536" />
    </inertial>
    <visual>
      <origin
        xyz="0 0 0"
        rpy="0 0 0" />
      <geometry>
        <box size="0.4 0.22 0.1"/>
        <!-- <mesh
          filename="package://longxiang/meshes/base.STL" /> -->
      </geometry>
      <material name="">
        <color rgba="0.75294 0.75294 0.75294 1" />
      </material>
    </visual>
    <collision>
      <origin
        xyz="0 0 0"
        rpy="0 0 0" />
      <geometry>
        <box size="0.4 0.22 0.1"/>
        <!-- <mesh
          filename="package://longxiang/meshes/base.STL" /> -->

      </geometry>
    </collision>
  </link>

  <!-- LF -->
  <link
    name="LF_hip">
    <inertial>
      <origin
        xyz="-0.0096065 -0.010937 3.9018E-06"
        rpy="0 0 0" />
      <mass
        value="0.32023" />
      <inertia
        ixx="0.00034375"
        ixy="-1.9666E-06"
        ixz="-3.4752E-07"
        iyy="0.00067021"
        iyz="1.2072E-07"
        izz="0.00038097" />
    </inertial>
    <visual>
      <origin
        xyz="0 0 0"
        rpy="0 0 0" />
      <geometry>
        <mesh
          filename="package://longxiang/meshes/LF_hip.STL" />
      </geometry>
      <material name="">
        <color rgba="0.75294 0.75294 0.75294 1" />
      </material>
    </visual>
    <collision>
      <origin
        xyz="0 0 0"
        rpy="0 0 0" />
      <geometry>
        <mesh
          filename="package://longxiang/meshes/LF_hip.STL" />
      </geometry>
    </collision>
  </link>
  <joint
    name="LF_HAA"
    type="revolute">
    <origin
      xyz="0.30236 0.07 -0.004"
      rpy="0 0 0" />
    <parent
      link="base" />
    <child
      link="LF_hip" />
    <axis
      xyz="1 0 0" />
    <limit
      lower="-3.14"
      upper="3.14"
      effort="50"
      velocity="21" />
  </joint>
  <link
    name="LF_thigh">
    <inertial>
      <origin
        xyz="-0.0036513 0.082785 -0.055599"
        rpy="0 0 0" />
      <mass
        value="0.45053" />
      <inertia
        ixx="0.0023919"
        ixy="-1.9911E-06"
        ixz="-0.00014907"
        iyy="0.0027926"
        iyz="-1.7498E-05"
        izz="0.00042652" />
    </inertial>
    <visual>
      <origin
        xyz="0 0 0"
        rpy="0 0 0" />
      <geometry>
        <mesh
          filename="package://longxiang/meshes/LF_thigh.STL" />
      </geometry>
      <material name="">
        <color rgba="0.75294 0.75294 0.75294 1" />
      </material>
    </visual>
    <collision>
      <origin
        xyz="0 0 0"
        rpy="0 0 0" />
      <geometry>
        <mesh
          filename="package://longxiang/meshes/LF_thigh.STL" />
      </geometry>
    </collision>
  </link>
  <joint
    name="LF_HFE"
    type="revolute">
    <origin
      xyz="0 0 0"
      rpy="0 0 0" />
    <parent
      link="LF_hip" />
    <child
      link="LF_thigh" />
    <axis
      xyz="0 1 0" />
    <limit
      lower="-3.14"
      upper="3.14"
      effort="50"
      velocity="21" />
  </joint>
  <link
    name="LF_calf">
    <inertial>
      <origin
        xyz="0.0027285 1.5133E-08 -0.17262"
        rpy="0 0 0" />
      <mass
        value="0.077851" />
      <inertia
        ixx="0.00072217"
        ixy="-3.2479E-11"
        ixz="1.7552E-05"
        iyy="0.00073008"
        iyz="1.6802E-08"
        izz="1.1436E-05" />
    </inertial>
    <visual>
      <origin
        xyz="0 0 0"
        rpy="0 0 0" />
      <geometry>
        <mesh
          filename="package://longxiang/meshes/LF_calf.STL" />
      </geometry>
      <material name="">
        <color rgba="0.75294 0.75294 0.75294 1" />
      </material>
    </visual>
    <collision>
      <origin
        xyz="0 0 0"
        rpy="0 0 0" />
      <geometry>
        <mesh
          filename="package://longxiang/meshes/LF_calf.STL" />
      </geometry>
    </collision>
  </link>
  <joint
    name="LF_KFE"
    type="revolute">
    <origin
      xyz="0 0.1057 -0.28"
      rpy="0 0 0" />
    <parent
      link="LF_thigh" />
    <child
      link="LF_calf" />
    <axis
      xyz="0 1 0" />
    <limit
      lower="-3.14"
      upper="3.14"
      effort="50"
      velocity="21" />
  </joint>

  <link name="LF_foot">
    <visual>
      <origin rpy="0 0 0" xyz="0 0 0"/>
      <geometry>
        <sphere radius="0.01"/>
      </geometry>
      <material name="">
        <color rgba="0.75294 0.75294 0.75294 1" />
      </material>
    </visual>
    <collision>
      <origin rpy="0 0 0" xyz="0 0 0"/>
      <geometry>
        <sphere radius="0.02"/>
      </geometry>
    </collision>
    <inertial>
      <mass value="0.06"/>
      <inertia ixx="9.600000000000001e-06" ixy="0.0" ixz="0.0" iyy="9.600000000000001e-06" iyz="0.0" izz="9.600000000000001e-06"/>
    </inertial>
  </link>
  <joint name="LF_FOOT" type="fixed">
    <origin rpy="0 0 0" xyz="0 0 -0.2668"/>
    <parent link="LF_calf"/>
    <child link="LF_foot"/>
  </joint>


  <!-- RF............ -->
  <link
    name="RF_hip">
    <inertial>
      <origin
        xyz="-0.0096065 0.010937 -4.1917E-06"
        rpy="0 0 0" />
      <mass
        value="0.32023" />
      <inertia
        ixx="0.00034375"
        ixy="1.9666E-06"
        ixz="3.479E-07"
        iyy="0.00067021"
        iyz="1.2072E-07"
        izz="0.00038097" />
    </inertial>
    <visual>
      <origin
        xyz="0 0 0"
        rpy="0 0 0" />
      <geometry>
        <mesh
          filename="package://longxiang/meshes/RF_hip.STL" />
      </geometry>
      <material name="">
        <color rgba="0.75294 0.75294 0.75294 1" />
      </material>
    </visual>
    <collision>
      <origin
        xyz="0 0 0"
        rpy="0 0 0" />
      <geometry>
        <mesh
          filename="package://longxiang/meshes/RF_hip.STL" />
      </geometry>
    </collision>
  </link>
  <joint
    name="RF_HAA"
    type="revolute">
    <origin
      xyz="0.30236 -0.07 -0.004"
      rpy="0 0 0" />
    <parent
      link="base" />
    <child
      link="RF_hip" />
    <axis
      xyz="1 0 0" />
    <limit
      lower="-3.14"
      upper="3.14"
      effort="50"
      velocity="21" />
  </joint>
  <link
    name="RF_thigh">
    <inertial>
      <origin
        xyz="-0.003594 -0.082799 -0.055838"
        rpy="0 0 0" />
      <mass
        value="0.45095" />
      <inertia
        ixx="0.0023942"
        ixy="1.9669E-06"
        ixz="-0.00015632"
        iyy="0.0028006"
        iyz="1.7322E-05"
        izz="0.00043223" />
    </inertial>
    <visual>
      <origin
        xyz="0 0 0"
        rpy="0 0 0" />
      <geometry>
        <mesh
          filename="package://longxiang/meshes/RF_thigh.STL" />
      </geometry>
      <material name="">
        <color rgba="0.75294 0.75294 0.75294 1" />
      </material>
    </visual>
    <collision>
      <origin
        xyz="0 0 0"
        rpy="0 0 0" />
      <geometry>
        <mesh
          filename="package://longxiang/meshes/RF_thigh.STL" />
      </geometry>
    </collision>
  </link>
  <joint
    name="RF_HFE"
    type="revolute">
    <origin
      xyz="0 0 0"
      rpy="0 0 0" />
    <parent
      link="RF_hip" />
    <child
      link="RF_thigh" />
    <axis
      xyz="0 1 0" />
    <limit
      lower="-3.14"
      upper="3.14"
      effort="50"
      velocity="21" />
  </joint>
  <link
    name="RF_calf">
    <inertial>
      <origin
        xyz="0.0027285 1.5136E-08 -0.17262"
        rpy="0 0 0" />
      <mass
        value="0.077851" />
      <inertia
        ixx="0.00072217"
        ixy="-3.2483E-11"
        ixz="1.7552E-05"
        iyy="0.00073008"
        iyz="1.6802E-08"
        izz="1.1436E-05" />
    </inertial>
    <visual>
      <origin
        xyz="0 0 0"
        rpy="0 0 0" />
      <geometry>
        <mesh
          filename="package://longxiang/meshes/RF_calf.STL" />
      </geometry>
      <material name="">
        <color rgba="0.75294 0.75294 0.75294 1" />
      </material>
    </visual>
    <collision>
      <origin
        xyz="0 0 0"
        rpy="0 0 0" />
      <geometry>
        <mesh
          filename="package://longxiang/meshes/RF_calf.STL" />
      </geometry>
    </collision>
  </link>
  <joint
    name="RF_KFE"
    type="revolute">
    <origin
      xyz="0 -0.1057 -0.28"
      rpy="0 0 0" />
    <parent
      link="RF_thigh" />
    <child
      link="RF_calf" />
    <axis
      xyz="0 1 0" />
    <limit
      lower="-3.14"
      upper="3.14"
      effort="50"
      velocity="21" />
  </joint>

  <link name="RF_foot">
    <visual>
      <origin rpy="0 0 0" xyz="0 0 0"/>
      <geometry>
        <sphere radius="0.01"/>
      </geometry>
      <material name="">
        <color rgba="0.75294 0.75294 0.75294 1" />
      </material>
    </visual>
    <collision>
      <origin rpy="0 0 0" xyz="0 0 0"/>
      <geometry>
        <sphere radius="0.02"/>
      </geometry>
    </collision>
    <inertial>
      <mass value="0.06"/>
      <inertia ixx="9.600000000000001e-06" ixy="0.0" ixz="0.0" iyy="9.600000000000001e-06" iyz="0.0" izz="9.600000000000001e-06"/>
    </inertial>
  </link>
  <joint name="RF_FOOT" type="fixed">
    <origin rpy="0 0 0" xyz="0 0 -0.2668"/>
    <parent link="RF_calf"/>
    <child link="RF_foot"/>
  </joint>

  <!-- LH -->
  <link
    name="LH_hip">
    <inertial>
      <origin
        xyz="0.0096065 -0.010937 -3.9018E-06"
        rpy="0 0 0" />
      <mass
        value="0.32023" />
      <inertia
        ixx="0.00034375"
        ixy="1.9666E-06"
        ixz="-3.4752E-07"
        iyy="0.00067021"
        iyz="-1.2072E-07"
        izz="0.00038097" />
    </inertial>
    <visual>
      <origin
        xyz="0 0 0"
        rpy="0 0 0" />
      <geometry>
        <mesh
          filename="package://longxiang/meshes/LH_hip.STL" />
      </geometry>
      <material name="">
        <color rgba="0.75294 0.75294 0.75294 1" />
      </material>
    </visual>
    <collision>
      <origin
        xyz="0 0 0"
        rpy="0 0 0" />
      <geometry>
        <mesh
          filename="package://longxiang/meshes/LH_hip.STL" />
      </geometry>
    </collision>
  </link>
  <joint
    name="LH_HAA"
    type="revolute">
    <origin
      xyz="-0.30236 0.07 -0.004"
      rpy="0 0 0" />
    <parent
      link="base" />
    <child
      link="LH_hip" />
    <axis
      xyz="1 0 0" />
    <limit
      lower="-3.14"
      upper="3.14"
      effort="50"
      velocity="21" />
  </joint>
  <link
    name="LH_thigh">
    <inertial>
      <origin
        xyz="-0.0036513 0.082785 -0.055599"
        rpy="0 0 0" />
      <mass
        value="0.45053" />
      <inertia
        ixx="0.0023919"
        ixy="-1.9911E-06"
        ixz="-0.00014907"
        iyy="0.0027926"
        iyz="-1.7498E-05"
        izz="0.00042652" />
    </inertial>
    <visual>
      <origin
        xyz="0 0 0"
        rpy="0 0 0" />
      <geometry>
        <mesh
          filename="package://longxiang/meshes/LH_thigh.STL" />
      </geometry>
      <material name="">
        <color rgba="0.75294 0.75294 0.75294 1" />
      </material>
    </visual>
    <collision>
      <origin
        xyz="0 0 0"
        rpy="0 0 0" />
      <geometry>
        <mesh
          filename="package://longxiang/meshes/LH_thigh.STL" />
      </geometry>
    </collision>
  </link>
  <joint
    name="LH_HFE"
    type="revolute">
    <origin
      xyz="0 0 0"
      rpy="0 0 0" />
    <parent
      link="LH_hip" />
    <child
      link="LH_thigh" />
    <axis
      xyz="0 1 0" />
    <limit
      lower="-3.14"
      upper="3.14"
      effort="50"
      velocity="21" />
  </joint>
  <link
    name="LH_calf">
    <inertial>
      <origin
        xyz="0.0027285 1.5133E-08 -0.17262"
        rpy="0 0 0" />
      <mass
        value="0.077851" />
      <inertia
        ixx="0.00072217"
        ixy="-3.2479E-11"
        ixz="1.7552E-05"
        iyy="0.00073008"
        iyz="1.6802E-08"
        izz="1.1436E-05" />
    </inertial>
    <visual>
      <origin
        xyz="0 0 0"
        rpy="0 0 0" />
      <geometry>
        <mesh
          filename="package://longxiang/meshes/LH_calf.STL" />
      </geometry>
      <material name="">
        <color rgba="0.75294 0.75294 0.75294 1" />
      </material>
    </visual>
    <collision>
      <origin
        xyz="0 0 0"
        rpy="0 0 0" />
      <geometry>
        <mesh
          filename="package://longxiang/meshes/LH_calf.STL" />
      </geometry>
    </collision>
  </link>
  <joint
    name="LH_KFE"
    type="revolute">
    <origin
      xyz="0 0.1057 -0.28"
      rpy="0 0 0" />
    <parent
      link="LH_thigh" />
    <child
      link="LH_calf" />
    <axis
      xyz="0 1 0" />
    <limit
      lower="-3.14"
      upper="3.14"
      effort="50"
      velocity="21" />
  </joint>

  <link name="LH_foot">
    <visual>
      <origin rpy="0 0 0" xyz="0 0 0"/>
      <geometry>
        <sphere radius="0.01"/>
      </geometry>
      <material name="">
        <color rgba="0.75294 0.75294 0.75294 1" />
      </material>
    </visual>
    <collision>
      <origin rpy="0 0 0" xyz="0 0 0"/>
      <geometry>
        <sphere radius="0.02"/>
      </geometry>
    </collision>
    <inertial>
      <mass value="0.06"/>
      <inertia ixx="9.600000000000001e-06" ixy="0.0" ixz="0.0" iyy="9.600000000000001e-06" iyz="0.0" izz="9.600000000000001e-06"/>
    </inertial>
  </link>
  <joint name="LH_FOOT" type="fixed">
    <origin rpy="0 0 0" xyz="0 0 -0.2668"/>
    <parent link="LH_calf"/>
    <child link="LH_foot"/>
  </joint>

  <!-- RH -->
  <link
    name="RH_hip">
    <inertial>
      <origin
        xyz="0.0096065 0.010937 4.1917E-06"
        rpy="0 0 0" />
      <mass
        value="0.32023" />
      <inertia
        ixx="0.00034375"
        ixy="-1.9666E-06"
        ixz="-3.479E-07"
        iyy="0.00067021"
        iyz="-1.2072E-07"
        izz="0.00038097" />
    </inertial>
    <visual>
      <origin
        xyz="0 0 0"
        rpy="0 0 0" />
      <geometry>
        <mesh
          filename="package://longxiang/meshes/RH_hip.STL" />
      </geometry>
      <material name="">
        <color rgba="0.75294 0.75294 0.75294 1" />
      </material>
    </visual>
    <collision>
      <origin
        xyz="0 0 0"
        rpy="0 0 0" />
      <geometry>
        <mesh
          filename="package://longxiang/meshes/RH_hip.STL" />
      </geometry>
    </collision>
  </link>
  <joint
    name="RH_HAA"
    type="revolute">
    <origin
      xyz="-0.30236 -0.07 -0.004"
      rpy="0 0 0" />
    <parent
      link="base" />
    <child
      link="RH_hip" />
    <axis
      xyz="1 0 0" />
    <limit
      lower="-3.14"
      upper="3.14"
      effort="50"
      velocity="21" />
  </joint>
  <link
    name="RH_thigh">
    <inertial>
      <origin
        xyz="-0.003594 -0.082799 -0.055838"
        rpy="0 0 0" />
      <mass
        value="0.45095" />
      <inertia
        ixx="0.0023942"
        ixy="1.9669E-06"
        ixz="-0.00015632"
        iyy="0.0028006"
        iyz="1.7322E-05"
        izz="0.00043223" />
    </inertial>
    <visual>
      <origin
        xyz="0 0 0"
        rpy="0 0 0" />
      <geometry>
        <mesh
          filename="package://longxiang/meshes/RH_thigh.STL" />
      </geometry>
      <material name="">
        <color rgba="0.75294 0.75294 0.75294 1" />
      </material>
    </visual>
    <collision>
      <origin
        xyz="0 0 0"
        rpy="0 0 0" />
      <geometry>
        <mesh
          filename="package://longxiang/meshes/RH_thigh.STL" />
      </geometry>
    </collision>
  </link>
  <joint
    name="RH_HFE"
    type="revolute">
    <origin
      xyz="0 0 0"
      rpy="0 0 0" />
    <parent
      link="RH_hip" />
    <child
      link="RH_thigh" />
    <axis
      xyz="0 1 0" />
    <limit
      lower="-3.14"
      upper="3.14"
      effort="50"
      velocity="21" />
  </joint>
  <link
    name="RH_calf">
    <inertial>
      <origin
        xyz="0.0027285 1.5136E-08 -0.17262"
        rpy="0 0 0" />
      <mass
        value="0.077851" />
      <inertia
        ixx="0.00072217"
        ixy="-3.2483E-11"
        ixz="1.7552E-05"
        iyy="0.00073008"
        iyz="1.6802E-08"
        izz="1.1436E-05" />
    </inertial>
    <visual>
      <origin
        xyz="0 0 0"
        rpy="0 0 0" />
      <geometry>
        <mesh
          filename="package://longxiang/meshes/RH_calf.STL" />
      </geometry>
      <material name="">
        <color rgba="0.75294 0.75294 0.75294 1" />
      </material>
    </visual>
    <collision>
      <origin
        xyz="0 0 0"
        rpy="0 0 0" />
      <geometry>
        <mesh
          filename="package://longxiang/meshes/RH_calf.STL" />
      </geometry>
    </collision>
  </link>
  <joint
    name="RH_KFE"
    type="revolute">
    <origin
      xyz="0 -0.1057 -0.28"
      rpy="0 0 0" />
    <parent
      link="RH_thigh" />
    <child
      link="RH_calf" />
    <axis
      xyz="0 1 0" />
    <limit
      lower="-3.14"
      upper="3.14"
      effort="50"
      velocity="21" />
  </joint>

  <link name="RH_foot">
    <visual>
      <origin rpy="0 0 0" xyz="0 0 0"/>
      <geometry>
        <sphere radius="0.01"/>
      </geometry>
      <material name="">
        <color rgba="0.75294 0.75294 0.75294 1" />
      </material>
    </visual>
    <collision>
      <origin rpy="0 0 0" xyz="0 0 0"/>
      <geometry>
        <sphere radius="0.02"/>
      </geometry>
    </collision>
    <inertial>
      <mass value="0.06"/>
      <inertia ixx="9.600000000000001e-06" ixy="0.0" ixz="0.0" iyy="9.600000000000001e-06" iyz="0.0" izz="9.600000000000001e-06"/>
    </inertial>
  </link>
  <joint name="RH_FOOT" type="fixed">
    <origin rpy="0 0 0" xyz="0 0 -0.2668"/>
    <parent link="RH_calf"/>
    <child link="RH_foot"/>
  </joint>

</robot>